<?xml version="1.0"?>
<!--
  Robot: my_robot
  Generated by: LinkForge v1.2.3
  https://github.com/arounamounchili/linkforge
  Date: 2026-02-17 03:53:01
-->
<robot name="my_robot">
  <!-- Materials -->
  <material name="b_Frame_001_">
    <color rgba="0.705882 0.705882 0.713726 1" />
  </material>
  <material name="b_Caster_fork_001_001">
    <color rgba="0.705882 0.705882 0.713726 1" />
  </material>
  <material name="b_Footplate_001_">
    <color rgba="0.329412 0.329412 0.329412 1" />
  </material>
  <material name="b_Footplate_001_001">
    <color rgba="0.329412 0.329412 0.329412 1" />
  </material>
  <material name="b_Seat_001_">
    <color rgba="0.419608 0.156863 0.145098 1" />
  </material>
  <material name="b_Backrest_001_">
    <color rgba="0.419608 0.156863 0.145098 1" />
  </material>
  <material name="b_Side_panel_001_">
    <color rgba="0.705882 0.705882 0.713726 1" />
  </material>
  <material name="b_Side_panel_001_001">
    <color rgba="0.705882 0.705882 0.713726 1" />
  </material>
  <material name="b_Armrest_001_">
    <color rgba="0.576471 0.047059 0 1" />
  </material>
  <material name="b_Armrest_001_001">
    <color rgba="0.576471 0.047059 0 1" />
  </material>
  <material name="b_Push_handle_001_001">
    <color rgba="0.576471 0.047059 0 1" />
  </material>
  <material name="b_Push_handle_001_">
    <color rgba="0.576471 0.047059 0 1" />
  </material>
  <material name="b_Pin_001_001">
    <color rgba="0.8 0.8 0.8 1" />
  </material>
  <material name="b_Pin_001_">
    <color rgba="0.8 0.8 0.8 1" />
  </material>
  <material name="b_Rear_wheel_001_001">
    <color rgba="0.196078 0.196078 0.196078 1" />
  </material>
  <material name="b_Rear_wheel_001_">
    <color rgba="0.196078 0.196078 0.196078 1" />
  </material>
  <material name="b_Caster_wheel_001_">
    <color rgba="0.196078 0.196078 0.196078 1" />
  </material>
  <material name="b_Caster_wheel_001_001">
    <color rgba="0.196078 0.196078 0.196078 1" />
  </material>
  <!-- Links -->
  <link name="base_link">
    <visual>
      <origin xyz="0.2159 -0.455574 -0.326007" rpy="0 0 0" />
      <geometry>
        <mesh filename="package://wheelchair_description/meshes/base_link_visual.stl" />
      </geometry>
      <material name="b_Frame_001_" />
    </visual>
    <collision>
      <origin xyz="0.2159 -0.455578 -0.326007" rpy="0 0 0" />
      <geometry>
        <mesh filename="package://wheelchair_description/meshes/base_link_collision.stl" />
      </geometry>
    </collision>
    <inertial>
      <mass value="1" />
      <inertia ixx="0.089727" ixy="0" ixz="0" iyy="0.062793" iyz="0.020276" izz="0.072745" />
    </inertial>
  </link>
  <link name="right_caster">
    <visual>
      <origin xyz="0.4318 -0.293335 -0.633983" rpy="0 0 0" />
      <geometry>
        <mesh filename="package://wheelchair_description/meshes/right_caster_visual.stl" />
      </geometry>
      <material name="b_Caster_fork_001_001" />
    </visual>
    <collision>
      <origin xyz="0.4318 -0.293335 -0.633983" rpy="0 0 0" />
      <geometry>
        <mesh filename="package://wheelchair_description/meshes/right_caster_collision.stl" />
      </geometry>
    </collision>
    <inertial>
      <mass value="1" />
      <inertia ixx="0.002167" ixy="0" ixz="0" iyy="0.002068" iyz="0.000541" izz="0.000631" />
    </inertial>
  </link>
  <link name="left_caster">
    <visual>
      <origin xyz="0 -0.293335 -0.633983" rpy="0 0 0" />
      <geometry>
        <mesh filename="package://wheelchair_description/meshes/left_caster_visual.stl" />
      </geometry>
      <material name="b_Caster_fork_001_001" />
    </visual>
    <collision>
      <origin xyz="0 -0.293335 -0.633983" rpy="0 0 0" />
      <geometry>
        <mesh filename="package://wheelchair_description/meshes/left_caster_collision.stl" />
      </geometry>
    </collision>
    <inertial>
      <mass value="1" />
      <inertia ixx="0.002167" ixy="0" ixz="0" iyy="0.002068" iyz="0.000541" izz="0.000631" />
    </inertial>
  </link>
  <link name="right_pedal">
    <visual>
      <origin xyz="0.34925 -0.057806 -0.687826" rpy="0 0 0" />
      <geometry>
        <mesh filename="package://wheelchair_description/meshes/right_pedal_visual.stl" />
      </geometry>
      <material name="b_Footplate_001_" />
    </visual>
    <collision>
      <origin xyz="0.34925 -0.057806 -0.687826" rpy="0 0 0" />
      <geometry>
        <mesh filename="package://wheelchair_description/meshes/right_pedal_collision.stl" />
      </geometry>
    </collision>
    <inertial>
      <mass value="1" />
      <inertia ixx="0.001777" ixy="0.000099" ixz="-0.000273" iyy="0.003236" iyz="-0.000468" izz="0.00435" />
    </inertial>
  </link>
  <link name="left_pedal">
    <visual>
      <origin xyz="0.08255 -0.057806 -0.687826" rpy="0 0 0" />
      <geometry>
        <mesh filename="package://wheelchair_description/meshes/left_pedal_visual.stl" />
      </geometry>
      <material name="b_Footplate_001_001" />
    </visual>
    <collision>
      <origin xyz="0.08255 -0.057806 -0.687826" rpy="0 0 0" />
      <geometry>
        <mesh filename="package://wheelchair_description/meshes/left_pedal_collision.stl" />
      </geometry>
    </collision>
    <inertial>
      <mass value="1" />
      <inertia ixx="0.001777" ixy="-0.000099" ixz="0.000273" iyy="0.003236" iyz="-0.000468" izz="0.00435" />
    </inertial>
  </link>
  <link name="seat">
    <visual>
      <origin xyz="0.216573 -0.558772 -0.439478" rpy="0 0 0" />
      <geometry>
        <mesh filename="package://wheelchair_description/meshes/seat_visual.stl" />
      </geometry>
      <material name="b_Seat_001_" />
    </visual>
    <collision>
      <origin xyz="0.216573 -0.558772 -0.439478" rpy="0 0 0" />
      <geometry>
        <mesh filename="package://wheelchair_description/meshes/seat_collision.stl" />
      </geometry>
    </collision>
    <inertial>
      <mass value="1" />
      <inertia ixx="0.012154" ixy="0" ixz="-0.000008" iyy="0.010543" iyz="0" izz="0.022582" />
    </inertial>
  </link>
  <link name="back">
    <visual>
      <origin xyz="0.224352 -0.79993 -0.177682" rpy="0 0 0" />
      <geometry>
        <mesh filename="package://wheelchair_description/meshes/back_visual.stl" />
      </geometry>
      <material name="b_Backrest_001_" />
    </visual>
    <collision>
      <origin xyz="0.224352 -0.79993 -0.177682" rpy="0 0 0" />
      <geometry>
        <mesh filename="package://wheelchair_description/meshes/back_collision.stl" />
      </geometry>
    </collision>
    <inertial>
      <mass value="1" />
      <inertia ixx="0.013019" ixy="0.000002" ixz="-0.000024" iyy="0.024066" iyz="0.000649" izz="0.011195" />
    </inertial>
  </link>
  <link name="right_panel">
    <visual>
      <origin xyz="0.453228 -0.554478 -0.282352" rpy="0 0 0" />
      <geometry>
        <mesh filename="package://wheelchair_description/meshes/right_panel_visual.stl" />
      </geometry>
      <material name="b_Side_panel_001_" />
    </visual>
    <collision>
      <origin xyz="0.453228 -0.554478 -0.282352" rpy="0 0 0" />
      <geometry>
        <mesh filename="package://wheelchair_description/meshes/right_panel_collision.stl" />
      </geometry>
    </collision>
    <inertial>
      <mass value="1" />
      <inertia ixx="0.022916" ixy="0" ixz="0" iyy="0.007613" iyz="0.001771" izz="0.015384" />
    </inertial>
  </link>
  <link name="left_panel">
    <visual>
      <origin xyz="-0.021428 -0.554478 -0.282352" rpy="0 0 0" />
      <geometry>
        <mesh filename="package://wheelchair_description/meshes/left_panel_visual.stl" />
      </geometry>
      <material name="b_Side_panel_001_001" />
    </visual>
    <collision>
      <origin xyz="-0.021428 -0.554478 -0.282352" rpy="0 0 0" />
      <geometry>
        <mesh filename="package://wheelchair_description/meshes/left_panel_collision.stl" />
      </geometry>
    </collision>
    <inertial>
      <mass value="1" />
      <inertia ixx="0.022916" ixy="0" ixz="0" iyy="0.007613" iyz="0.001771" izz="0.015384" />
    </inertial>
  </link>
  <link name="right_armrest">
    <visual>
      <origin xyz="0.453217 -0.626837 -0.113286" rpy="0 0 0" />
      <geometry>
        <mesh filename="package://wheelchair_description/meshes/right_armrest_visual.stl" />
      </geometry>
      <material name="b_Armrest_001_" />
    </visual>
    <collision>
      <origin xyz="0.453217 -0.626837 -0.113286" rpy="0 0 0" />
      <geometry>
        <mesh filename="package://wheelchair_description/meshes/right_armrest_collision.stl" />
      </geometry>
    </collision>
    <inertial>
      <mass value="1" />
      <inertia ixx="0.004929" ixy="0" ixz="0" iyy="0.000325" iyz="0" izz="0.005095" />
    </inertial>
  </link>
  <link name="left_armrest">
    <visual>
      <origin xyz="-0.021373 -0.625889 -0.113303" rpy="0 0 0" />
      <geometry>
        <mesh filename="package://wheelchair_description/meshes/left_armrest_visual.stl" />
      </geometry>
      <material name="b_Armrest_001_001" />
    </visual>
    <collision>
      <origin xyz="-0.021373 -0.625889 -0.113303" rpy="0 0 0" />
      <geometry>
        <mesh filename="package://wheelchair_description/meshes/left_armrest_collision.stl" />
      </geometry>
    </collision>
    <inertial>
      <mass value="1" />
      <inertia ixx="0.004929" ixy="0" ixz="0.000001" iyy="0.000325" iyz="0" izz="0.005095" />
    </inertial>
  </link>
  <link name="right_handle">
    <visual>
      <origin xyz="0.4318 -0.878328 0.067693" rpy="0 0 0" />
      <geometry>
        <mesh filename="package://wheelchair_description/meshes/right_handle_visual.stl" />
      </geometry>
      <material name="b_Push_handle_001_001" />
    </visual>
    <collision>
      <origin xyz="0.4318 -0.878328 0.067693" rpy="0 0 0" />
      <geometry>
        <mesh filename="package://wheelchair_description/meshes/right_handle_collision.stl" />
      </geometry>
    </collision>
    <inertial>
      <mass value="1" />
      <inertia ixx="0.000804" ixy="0" ixz="0" iyy="0.000102" iyz="0" izz="0.000804" />
    </inertial>
  </link>
  <link name="left_handle">
    <visual>
      <origin xyz="0 -0.878328 0.067693" rpy="0 0 0" />
      <geometry>
        <mesh filename="package://wheelchair_description/meshes/left_handle_visual.stl" />
      </geometry>
      <material name="b_Push_handle_001_" />
    </visual>
    <collision>
      <origin xyz="0 -0.878328 0.067693" rpy="0 0 0" />
      <geometry>
        <mesh filename="package://wheelchair_description/meshes/left_handle_collision.stl" />
      </geometry>
    </collision>
    <inertial>
      <mass value="1" />
      <inertia ixx="0.000804" ixy="0" ixz="0" iyy="0.000102" iyz="0" izz="0.000804" />
    </inertial>
  </link>
  <link name="right_pin">
    <visual>
      <origin xyz="0.4318 -0.266347 -0.713358" rpy="0 0 0" />
      <geometry>
        <mesh filename="package://wheelchair_description/meshes/right_pin_visual.stl" />
      </geometry>
      <material name="b_Pin_001_001" />
    </visual>
    <collision>
      <origin xyz="0.4318 -0.266347 -0.713358" rpy="0 0 0" />
      <geometry>
        <mesh filename="package://wheelchair_description/meshes/right_pin_collision.stl" />
      </geometry>
    </collision>
    <inertial>
      <mass value="1" />
      <inertia ixx="0.000008" ixy="0" ixz="0" iyy="0.000307" iyz="0" izz="0.000307" />
    </inertial>
  </link>
  <link name="left_pin">
    <visual>
      <origin xyz="0 -0.266347 -0.713358" rpy="0 0 0" />
      <geometry>
        <mesh filename="package://wheelchair_description/meshes/left_pin_visual.stl" />
      </geometry>
      <material name="b_Pin_001_" />
    </visual>
    <collision>
      <origin xyz="0 -0.266347 -0.713358" rpy="0 0 0" />
      <geometry>
        <mesh filename="package://wheelchair_description/meshes/left_pin_collision.stl" />
      </geometry>
    </collision>
    <inertial>
      <mass value="1" />
      <inertia ixx="0.000008" ixy="0" ixz="0" iyy="0.000307" iyz="0" izz="0.000307" />
    </inertial>
  </link>
  <link name="rightbackwheel">
    <visual>
      <origin xyz="-0.028701 -0.000077 -0.000413" rpy="0 0 0" />
      <geometry>
        <mesh filename="package://wheelchair_description/meshes/rightbackwheel_visual.stl" />
      </geometry>
      <material name="b_Rear_wheel_001_001" />
    </visual>
    <collision>
      <origin xyz="-0.028701 -0.000077 -0.000413" rpy="0 0 0" />
      <geometry>
        <mesh filename="package://wheelchair_description/meshes/rightbackwheel_collision.stl" />
      </geometry>
    </collision>
    <inertial>
      <mass value="1" />
      <inertia ixx="0.040936" ixy="0" ixz="0" iyy="0.020867" iyz="0" izz="0.020867" />
    </inertial>
  </link>
  <link name="leftbackwheel">
    <visual>
      <origin xyz="0.028684 0.000118 -0.000308" rpy="0 0 0" />
      <geometry>
        <mesh filename="package://wheelchair_description/meshes/leftbackwheel_visual.stl" />
      </geometry>
      <material name="b_Rear_wheel_001_" />
    </visual>
    <collision>
      <origin xyz="0.028684 0.000118 -0.000308" rpy="0 0 0" />
      <geometry>
        <mesh filename="package://wheelchair_description/meshes/leftbackwheel_collision.stl" />
      </geometry>
    </collision>
    <inertial>
      <mass value="1" />
      <inertia ixx="0.040937" ixy="0" ixz="0" iyy="0.020867" iyz="0" izz="0.020867" />
    </inertial>
  </link>
  <link name="leftfrontwheel">
    <visual>
      <origin xyz="0 0 -0.000052" rpy="0 0 0" />
      <geometry>
        <mesh filename="package://wheelchair_description/meshes/leftfrontwheel_visual.stl" />
      </geometry>
      <material name="b_Caster_wheel_001_" />
    </visual>
    <collision>
      <origin xyz="0 0 -0.000052" rpy="0 0 0" />
      <geometry>
        <mesh filename="package://wheelchair_description/meshes/leftfrontwheel_collision.stl" />
      </geometry>
    </collision>
    <inertial>
      <mass value="1" />
      <inertia ixx="0.003811" ixy="0" ixz="0" iyy="0.002029" iyz="0" izz="0.002029" />
    </inertial>
  </link>
  <link name="rightfrontwheel">
    <visual>
      <origin xyz="0.000002 0 -0.000052" rpy="0 0 0" />
      <geometry>
        <mesh filename="package://wheelchair_description/meshes/rightfrontwheel_visual.stl" />
      </geometry>
      <material name="b_Caster_wheel_001_001" />
    </visual>
    <collision>
      <origin xyz="0.000002 0 -0.000052" rpy="0 0 0" />
      <geometry>
        <mesh filename="package://wheelchair_description/meshes/rightfrontwheel_collision.stl" />
      </geometry>
    </collision>
    <inertial>
      <mass value="1" />
      <inertia ixx="0.003811" ixy="0" ixz="0" iyy="0.002029" iyz="0" izz="0.002029" />
    </inertial>
  </link>
  <!-- Joints -->
  <joint name="right_caster_joint" type="fixed">
    <parent link="base_link" />
    <child link="right_caster" />
  </joint>
  <joint name="left_caster_joint" type="fixed">
    <parent link="base_link" />
    <child link="left_caster" />
  </joint>
  <joint name="right_pedal_joint" type="fixed">
    <parent link="base_link" />
    <child link="right_pedal" />
  </joint>
  <joint name="left_pedal_joint" type="fixed">
    <parent link="base_link" />
    <child link="left_pedal" />
  </joint>
  <joint name="seat_joint" type="fixed">
    <parent link="base_link" />
    <child link="seat" />
  </joint>
  <joint name="back_joint" type="fixed">
    <parent link="base_link" />
    <child link="back" />
  </joint>
  <joint name="right_panel_joint" type="fixed">
    <parent link="base_link" />
    <child link="right_panel" />
  </joint>
  <joint name="left_panel_joint" type="fixed">
    <parent link="base_link" />
    <child link="left_panel" />
  </joint>
  <joint name="right_armrest_joint" type="fixed">
    <parent link="right_panel" />
    <child link="right_armrest" />
  </joint>
  <joint name="left_armrest_joint" type="fixed">
    <parent link="left_panel" />
    <child link="left_armrest" />
  </joint>
  <joint name="right_handle_joint" type="fixed">
    <parent link="base_link" />
    <child link="right_handle" />
  </joint>
  <joint name="left_handle_joint" type="fixed">
    <parent link="base_link" />
    <child link="left_handle" />
  </joint>
  <joint name="right_pin_joint" type="fixed">
    <parent link="right_caster" />
    <child link="right_pin" />
  </joint>
  <joint name="left_pin_joint" type="fixed">
    <parent link="left_caster" />
    <child link="left_pin" />
  </joint>
  <joint name="rightbackwheel_joint" type="continuous">
    <origin xyz="0.52825 -0.7703 -0.516094" rpy="0 0 0" />
    <parent link="base_link" />
    <child link="rightbackwheel" />
    <axis xyz="1 0 0" />
    <limit effort="100" velocity="100" />
  </joint>
  <joint name="leftbackwheel_joint" type="continuous">
    <origin xyz="-0.096433 -0.770495 -0.516199" rpy="0 0 0" />
    <parent link="base_link" />
    <child link="leftbackwheel" />
    <axis xyz="1 0 0" />
    <limit effort="100" velocity="100" />
  </joint>
  <joint name="leftfrontwheel_joint" type="continuous">
    <origin xyz="0 -0.266347 -0.713306" rpy="0 0 0" />
    <parent link="left_caster" />
    <child link="leftfrontwheel" />
    <axis xyz="1 0 0" />
    <limit effort="100" velocity="100" />
  </joint>
  <joint name="rightfrontwheel_joint" type="continuous">
    <origin xyz="0.431798 -0.266347 -0.713306" rpy="0 0 0" />
    <parent link="right_caster" />
    <child link="rightfrontwheel" />
    <axis xyz="1 0 0" />
    <limit effort="100" velocity="100" />
  </joint>
</robot>